<?xml version="1.0"?>
<robot name="simple_diff_drive_robot" xmlns:xacro="http://www.ros.org/wiki/xacro">

  <!-- ===================== -->
  <!-- Properties -->
  <!-- ===================== -->

  <xacro:property name="base_length" value="0.35"/>
  <xacro:property name="base_width" value="0.25"/>
  <xacro:property name="base_height" value="0.12"/>

  <xacro:property name="wheel_radius" value="0.05"/>
  <xacro:property name="wheel_width" value="0.03"/>
  <xacro:property name="wheel_y_offset" value="0.14"/>
  <xacro:property name="wheel_x_offset" value="0.0"/>
  <xacro:property name="wheel_z_offset" value="${wheel_radius}"/>

  <xacro:property name="caster_radius" value="0.025"/>
  <xacro:property name="caster_x_offset" value="-0.13"/>
  <xacro:property name="caster_z_offset" value="${caster_radius}"/>

  <xacro:property name="laser_x_offset" value="0.18"/>
  <xacro:property name="laser_z_offset" value="0.14"/>

  <!-- Approximate inertial values -->
  <xacro:property name="base_mass" value="2.0"/>

  <!-- ===================== -->
  <!-- Materials -->
  <!-- ===================== -->

  <material name="blue">
    <color rgba="0.1 0.3 0.9 1.0"/>
  </material>

  <material name="black">
    <color rgba="0.02 0.02 0.02 1.0"/>
  </material>

  <material name="gray">
    <color rgba="0.5 0.5 0.5 1.0"/>
  </material>

  <material name="red">
    <color rgba="1.0 0.0 0.0 1.0"/>
  </material>

  <!-- ===================== -->
  <!-- Base Link -->
  <!-- ===================== -->

  <link name="base_link">
    <visual>
      <origin xyz="0 0 ${base_height / 2.0 + wheel_radius}" rpy="0 0 0"/>
      <geometry>
        <box size="${base_length} ${base_width} ${base_height}"/>
      </geometry>
      <material name="blue"/>
    </visual>

    <collision>
      <origin xyz="0 0 ${base_height / 2.0 + wheel_radius}" rpy="0 0 0"/>
      <geometry>
        <box size="${base_length} ${base_width} ${base_height}"/>
      </geometry>
    </collision>

    <inertial>
      <origin xyz="0 0 ${base_height / 2.0 + wheel_radius}" rpy="0 0 0"/>
      <mass value="${base_mass}"/>
      <inertia
        ixx="0.02" ixy="0.0" ixz="0.0"
        iyy="0.02" iyz="0.0"
        izz="0.02"/>
    </inertial>
  </link>

  <!-- ===================== -->
  <!-- Wheel Macro -->
  <!-- ===================== -->

  <xacro:macro name="wheel" params="prefix y_offset">
    <link name="${prefix}_wheel_link">
      <visual>
        <origin xyz="0 0 0" rpy="1.5708 0 0"/>
        <geometry>
          <cylinder radius="${wheel_radius}" length="${wheel_width}"/>
        </geometry>
        <material name="black"/>
      </visual>

      <collision>
        <origin xyz="0 0 0" rpy="1.5708 0 0"/>
        <geometry>
          <cylinder radius="${wheel_radius}" length="${wheel_width}"/>
        </geometry>
      </collision>

      <inertial>
        <origin xyz="0 0 0" rpy="0 0 0"/>
        <mass value="0.2"/>
        <inertia
          ixx="0.001" ixy="0.0" ixz="0.0"
          iyy="0.001" iyz="0.0"
          izz="0.001"/>
      </inertial>
    </link>

    <joint name="${prefix}_wheel_joint" type="continuous">
      <parent link="base_link"/>
      <child link="${prefix}_wheel_link"/>
      <origin xyz="${wheel_x_offset} ${y_offset} ${wheel_z_offset}" rpy="0 0 0"/>
      <axis xyz="0 1 0"/>
    </joint>
  </xacro:macro>

  <xacro:wheel prefix="left" y_offset="${wheel_y_offset}"/>
  <xacro:wheel prefix="right" y_offset="${-wheel_y_offset}"/>

  <!-- ===================== -->
  <!-- Caster -->
  <!-- ===================== -->

  <link name="caster_link">
    <visual>
      <origin xyz="0 0 0" rpy="0 0 0"/>
      <geometry>
        <sphere radius="${caster_radius}"/>
      </geometry>
      <material name="gray"/>
    </visual>

    <collision>
      <origin xyz="0 0 0" rpy="0 0 0"/>
      <geometry>
        <sphere radius="${caster_radius}"/>
      </geometry>
    </collision>
  </link>

  <joint name="caster_joint" type="fixed">
    <parent link="base_link"/>
    <child link="caster_link"/>
    <origin xyz="${caster_x_offset} 0 ${caster_z_offset}" rpy="0 0 0"/>
  </joint>

  <!-- ===================== -->
  <!-- Laser Link -->
  <!-- ===================== -->

  <link name="laser_link">
    <visual>
      <origin xyz="0 0 0" rpy="0 0 0"/>
      <geometry>
        <box size="0.06 0.04 0.03"/>
      </geometry>
      <material name="red"/>
    </visual>
  </link>

  <joint name="laser_joint" type="fixed">
    <parent link="base_link"/>
    <child link="laser_link"/>
    <origin xyz="${laser_x_offset} 0 ${laser_z_offset}" rpy="0 0 0"/>
  </joint>

</robot>
